<sdf version='1.7'>
  <model name='robot_mk2'>
    <link name='base_link'>
      <inertial>
        <pose>-1e-06 -0.01155 0.053193 0 -0 0</pose>
        <mass>5.35852</mass>
        <inertia>
          <ixx>0.0719018</ixx>
          <ixy>-1.24143e-05</ixy>
          <ixz>8.05932e-09</ixz>
          <iyy>0.0809954</iyy>
          <iyz>-6.26768e-07</iyz>
          <izz>0.137156</izz>
        </inertia>
      </inertial>
      <collision name='base_link_collision'>
        <pose>0 0 0 0 -0 0</pose>
        <geometry>
          <mesh>
            <scale>1 1 1</scale>
            <uri>model://rovermk2_description/meshes/base_link.STL</uri>
          </mesh>
        </geometry>
      </collision>
      <collision name='base_link_fixed_joint_lump__suspension_left_collision_1'>
        <pose>-0.175 -0.1 0.043 0 0 -1.5708</pose>
        <geometry>
          <mesh>
            <scale>1 1 1</scale>
            <uri>model://rovermk2_description/meshes/suspension_1.STL</uri>
          </mesh>
        </geometry>
      </collision>
      <collision name='base_link_fixed_joint_lump__suspension_right_collision_2'>
        <pose>0.2225 -0.01 0.043 0 1.8e-05 -1.5708</pose>
        <geometry>
          <mesh>
            <scale>1 1 1</scale>
            <uri>model://rovermk2_description/meshes/suspension_2.STL</uri>
          </mesh>
        </geometry>
      </collision>
      <visual name='base_link_visual'>
        <pose>0 0 0 0 -0 0</pose>
        <geometry>
          <mesh>
            <scale>1 1 1</scale>
            <uri>model://rovermk2_description/meshes/base_link.STL</uri>
          </mesh>
        </geometry>
      </visual>
      <visual name='base_link_fixed_joint_lump__imu_link_visual_1'>
        <pose>0 0 0 0 -0 0</pose>
        <geometry>
          <box>
            <size>0.01 0.01 0.01</size>
          </box>
        </geometry>
      </visual>
      <visual name='base_link_fixed_joint_lump__suspension_left_visual_2'>
        <pose>-0.175 -0.1 0.043 0 0 -1.5708</pose>
        <geometry>
          <mesh>
            <scale>1 1 1</scale>
            <uri>model://rovermk2_description/meshes/suspension_1.STL</uri>
          </mesh>
        </geometry>
      </visual>
      <visual name='base_link_fixed_joint_lump__suspension_right_visual_3'>
        <pose>0.2225 -0.01 0.043 0 1.8e-05 -1.5708</pose>
        <geometry>
          <mesh>
            <scale>1 1 1</scale>
            <uri>model://rovermk2_description/meshes/suspension_2.STL</uri>
          </mesh>
        </geometry>
      </visual>
      <sensor name='imu_sensor' type='imu'>
        <always_on>1</always_on>
        <update_rate>100</update_rate>
        <visualize>1</visualize>
        <topic>imu</topic>
        <pose>0 0 0 0 -0 0</pose>
        <ignition_frame_id>imu_link</ignition_frame_id>
      </sensor>
    </link>
    <joint name='steerBL_joint' type='revolute'>
      <pose relative_to='base_link'>-0.175001 -0.3175 0.008 0 0 -1.5708</pose>
      <parent>base_link</parent>
      <child>steer_BL</child>
      <axis>
        <xyz>0 0 1</xyz>
        <limit>
          <lower>-1e+16</lower>
          <upper>1e+16</upper>
        </limit>
        <dynamics>
          <spring_reference>0</spring_reference>
          <spring_stiffness>0</spring_stiffness>
        </dynamics>
      </axis>
    </joint>
    <link name='steer_BL'>
      <pose relative_to='steerBL_joint'>0 0 0 0 -0 0</pose>
      <inertial>
        <pose>-0 -0.032335 -0.05247 0 -0 0</pose>
        <mass>0.1576</mass>
        <inertia>
          <ixx>0.00057382</ixx>
          <ixy>-9.7292e-20</ixy>
          <ixz>-4.0506e-19</ixz>
          <iyy>0.00051647</iyy>
          <iyz>-0.00013791</iyz>
          <izz>0.00023455</izz>
        </inertia>
      </inertial>
      <collision name='steer_BL_collision'>
        <pose>0 0 0 0 -0 0</pose>
        <geometry>
          <mesh>
            <scale>1 1 1</scale>
            <uri>model://rovermk2_description/meshes/steer_BL.STL</uri>
          </mesh>
        </geometry>
      </collision>
      <visual name='steer_BL_visual'>
        <pose>0 0 0 0 -0 0</pose>
        <geometry>
          <mesh>
            <scale>1 1 1</scale>
            <uri>model://rovermk2_description/meshes/steer_BL.STL</uri>
          </mesh>
        </geometry>
      </visual>
    </link>
    <joint name='wheelBL_joint' type='revolute'>
      <pose relative_to='steer_BL'>0 0.008 -0.127 0 -0.19461 -3.14159</pose>
      <parent>steer_BL</parent>
      <child>wheelBL</child>
      <axis>
        <xyz>0 -1 0</xyz>
        <limit>
          <lower>-1e+16</lower>
          <upper>1e+16</upper>
        </limit>
        <dynamics>
          <spring_reference>0</spring_reference>
          <spring_stiffness>0</spring_stiffness>
        </dynamics>
      </axis>
    </joint>
    <link name='wheelBL'>
      <pose relative_to='wheelBL_joint'>0 0 0 0 -0 0</pose>
      <inertial>
        <pose>-1.5e-05 8e-06 -8e-06 0 -0 0</pose>
        <mass>0.57701</mass>
        <inertia>
          <ixx>0.0021482</ixx>
          <ixy>-3.9981e-08</ixy>
          <ixz>-7.3417e-08</ixz>
          <iyy>0.0038226</iyy>
          <iyz>-2.1036e-08</iyz>
          <izz>0.0021482</izz>
        </inertia>
      </inertial>
      <collision name='wheelBL_collision'>
        <pose>0 0 0 0 -0 0</pose>
        <geometry>
          <mesh>
            <scale>1 1 1</scale>
            <uri>model://rovermk2_description/meshes/wheelBL.STL</uri>
          </mesh>
        </geometry>
      </collision>
      <visual name='wheelBL_visual'>
        <pose>0 0 0 0 -0 0</pose>
        <geometry>
          <mesh>
            <scale>1 1 1</scale>
            <uri>model://rovermk2_description/meshes/wheelBL.STL</uri>
          </mesh>
        </geometry>
      </visual>
    </link>
    <joint name='steerFL_joint' type='revolute'>
      <pose relative_to='base_link'>-0.174999 0.2975 0.008 0 0 -1.5708</pose>
      <parent>base_link</parent>
      <child>steerFL</child>
      <axis>
        <xyz>0 0 1</xyz>
        <limit>
          <lower>-1e+16</lower>
          <upper>1e+16</upper>
        </limit>
        <dynamics>
          <spring_reference>0</spring_reference>
          <spring_stiffness>0</spring_stiffness>
        </dynamics>
      </axis>
    </joint>
    <link name='steerFL'>
      <pose relative_to='steerFL_joint'>0 0 0 0 -0 0</pose>
      <inertial>
        <pose>-0 -0.032335 -0.05247 0 -0 0</pose>
        <mass>0.1576</mass>
        <inertia>
          <ixx>0.00057382</ixx>
          <ixy>7.8164e-19</ixy>
          <ixz>1.4837e-18</ixz>
          <iyy>0.00051647</iyy>
          <iyz>-0.00013791</iyz>
          <izz>0.00023455</izz>
        </inertia>
      </inertial>
      <collision name='steerFL_collision'>
        <pose>0 0 0 0 -0 0</pose>
        <geometry>
          <mesh>
            <scale>1 1 1</scale>
            <uri>model://rovermk2_description/meshes/Steer_FL_1.STL</uri>
          </mesh>
        </geometry>
      </collision>
      <visual name='steerFL_visual'>
        <pose>0 0 0 0 -0 0</pose>
        <geometry>
          <mesh>
            <scale>1 1 1</scale>
            <uri>model://rovermk2_description/meshes/Steer_FL_1.STL</uri>
          </mesh>
        </geometry>
      </visual>
    </link>
    <joint name='wheelFL_joint' type='revolute'>
      <pose relative_to='steerFL'>0 0.008 -0.127 0 -0.031506 -3.14159</pose>
      <parent>steerFL</parent>
      <child>wheelFL</child>
      <axis>
        <xyz>0 -1 0</xyz>
        <limit>
          <lower>-1e+16</lower>
          <upper>1e+16</upper>
        </limit>
        <dynamics>
          <spring_reference>0</spring_reference>
          <spring_stiffness>0</spring_stiffness>
        </dynamics>
      </axis>
    </joint>
    <link name='wheelFL'>
      <pose relative_to='wheelFL_joint'>0 0 0 0 -0 0</pose>
      <inertial>
        <pose>-1.2e-05 1.1e-05 -1e-05 0 -0 0</pose>
        <mass>0.57698</mass>
        <inertia>
          <ixx>0.0021487</ixx>
          <ixy>-1.7024e-08</ixy>
          <ixz>-8.7398e-08</ixz>
          <iyy>0.0038235</iyy>
          <iyz>8.3831e-09</iyz>
          <izz>0.0021487</izz>
        </inertia>
      </inertial>
      <collision name='wheelFL_collision'>
        <pose>0 0 0 0 -0 0</pose>
        <geometry>
          <mesh>
            <scale>1 1 1</scale>
            <uri>model://rovermk2_description/meshes/wheelFL.STL</uri>
          </mesh>
        </geometry>
      </collision>
      <visual name='wheelFL_visual'>
        <pose>0 0 0 0 -0 0</pose>
        <geometry>
          <mesh>
            <scale>1 1 1</scale>
            <uri>model://rovermk2_description/meshes/wheelFL.STL</uri>
          </mesh>
        </geometry>
      </visual>
    </link>
    <joint name='steerBR_joint' type='revolute'>
      <pose relative_to='base_link'>0.229263 -0.01 0.043199 -0 -1.8e-05 1.5708</pose>
      <parent>base_link</parent>
      <child>steer_BR</child>
      <axis>
        <xyz>6e-05 0 1</xyz>
        <limit>
          <lower>-1e+16</lower>
          <upper>1e+16</upper>
        </limit>
        <dynamics>
          <spring_reference>0</spring_reference>
          <spring_stiffness>0</spring_stiffness>
        </dynamics>
      </axis>
    </joint>
    <link name='steer_BR'>
      <pose relative_to='steerBR_joint'>0 0 0 0 -0 0</pose>
      <inertial>
        <pose>-0.30751 0.021928 -0.087669 0 -0 0</pose>
        <mass>0.1576</mass>
        <inertia>
          <ixx>0.00057382</ixx>
          <ixy>-5.2157e-17</ixy>
          <ixz>-1.2839e-16</ixz>
          <iyy>0.00051647</iyy>
          <iyz>-0.00013791</iyz>
          <izz>0.00023455</izz>
        </inertia>
      </inertial>
      <collision name='steer_BR_collision'>
        <pose>0 0 0 0 -0 0</pose>
        <geometry>
          <mesh>
            <scale>1 1 1</scale>
            <uri>model://rovermk2_description/meshes/steer_BR.STL</uri>
          </mesh>
        </geometry>
      </collision>
      <visual name='steer_BR_visual'>
        <pose>0 0 0 0 -0 0</pose>
        <geometry>
          <mesh>
            <scale>1 1 1</scale>
            <uri>model://rovermk2_description/meshes/steer_BR.STL</uri>
          </mesh>
        </geometry>
      </visual>
    </link>
    <joint name='wheelBR_joint' type='revolute'>
      <pose relative_to='steer_BR'>-0.30751 0.052263 -0.1622 0 -0.069204 0</pose>
      <parent>steer_BR</parent>
      <child>wheelBR</child>
      <axis>
        <xyz>0 -1 0</xyz>
        <limit>
          <lower>-1e+16</lower>
          <upper>1e+16</upper>
        </limit>
        <dynamics>
          <spring_reference>0</spring_reference>
          <spring_stiffness>0</spring_stiffness>
        </dynamics>
      </axis>
    </joint>
    <link name='wheelBR'>
      <pose relative_to='wheelBR_joint'>0 0 0 0 -0 0</pose>
      <inertial>
        <pose>-1.3e-05 1e-05 -9e-06 0 -0 0</pose>
        <mass>0.577</mass>
        <inertia>
          <ixx>0.0021487</ixx>
          <ixy>-1.7024e-08</ixy>
          <ixz>-8.7398e-08</ixz>
          <iyy>0.0038235</iyy>
          <iyz>8.3831e-09</iyz>
          <izz>0.0021487</izz>
        </inertia>
      </inertial>
      <collision name='wheelBR_collision'>
        <pose>0 0 0 0 -0 0</pose>
        <geometry>
          <mesh>
            <scale>1 1 1</scale>
            <uri>model://rovermk2_description/meshes/wheelBR.STL</uri>
          </mesh>
        </geometry>
      </collision>
      <visual name='wheelBR_visual'>
        <pose>0 0 0 0 -0 0</pose>
        <geometry>
          <mesh>
            <scale>1 1 1</scale>
            <uri>model://rovermk2_description/meshes/wheelBR.STL</uri>
          </mesh>
        </geometry>
      </visual>
    </link>
    <joint name='steerFR_joint' type='revolute'>
      <pose relative_to='base_link'>0.2325 -0.01 0.043 -0 -1.8e-05 1.5708</pose>
      <parent>base_link</parent>
      <child>steer_FR</child>
      <axis>
        <xyz>6e-05 0 1</xyz>
        <limit>
          <lower>-1e+16</lower>
          <upper>1e+16</upper>
        </limit>
        <dynamics>
          <spring_reference>0</spring_reference>
          <spring_stiffness>0</spring_stiffness>
        </dynamics>
      </axis>
    </joint>
    <link name='steer_FR'>
      <pose relative_to='steerFR_joint'>0 0 0 0 -0 0</pose>
      <inertial>
        <pose>0.3075 0.025165 -0.08747 0 -0 0</pose>
        <mass>0.1576</mass>
        <inertia>
          <ixx>0.00057382</ixx>
          <ixy>-5.4704e-17</ixy>
          <ixz>-1.3425e-16</ixz>
          <iyy>0.00051647</iyy>
          <iyz>-0.00013791</iyz>
          <izz>0.00023455</izz>
        </inertia>
      </inertial>
      <collision name='steer_FR_collision'>
        <pose>0 0 0 0 -0 0</pose>
        <geometry>
          <mesh>
            <scale>1 1 1</scale>
            <uri>model://rovermk2_description/meshes/steer_FR.STL</uri>
          </mesh>
        </geometry>
      </collision>
      <visual name='steer_FR_visual'>
        <pose>0 0 0 0 -0 0</pose>
        <geometry>
          <mesh>
            <scale>1 1 1</scale>
            <uri>model://rovermk2_description/meshes/steer_FR.STL</uri>
          </mesh>
        </geometry>
      </visual>
    </link>
    <joint name='wheelFR_joint' type='revolute'>
      <pose relative_to='steer_FR'>0.3075 0.0555 -0.162 0 -0.48916 0</pose>
      <parent>steer_FR</parent>
      <child>wheelFR</child>
      <axis>
        <xyz>0 -1 0</xyz>
        <limit>
          <lower>-1e+16</lower>
          <upper>1e+16</upper>
        </limit>
        <dynamics>
          <spring_reference>0</spring_reference>
          <spring_stiffness>0</spring_stiffness>
        </dynamics>
      </axis>
    </joint>
    <link name='wheelFR'>
      <pose relative_to='wheelFR_joint'>0 0 0 0 -0 0</pose>
      <inertial>
        <pose>-1.5e-05 8e-06 -7e-06 0 -0 0</pose>
        <mass>0.57701</mass>
        <inertia>
          <ixx>0.0021486</ixx>
          <ixy>-4.1925e-08</ixy>
          <ixz>-2.4022e-08</ixz>
          <iyy>0.0038235</iyy>
          <iyz>-1.3635e-08</iyz>
          <izz>0.0021489</izz>
        </inertia>
      </inertial>
      <collision name='wheelFR_collision'>
        <pose>0 0 0 0 -0 0</pose>
        <geometry>
          <mesh>
            <scale>1 1 1</scale>
            <uri>model://rovermk2_description/meshes/wheelFR.STL</uri>
          </mesh>
        </geometry>
      </collision>
      <visual name='wheelFR_visual'>
        <pose>0 0 0 0 -0 0</pose>
        <geometry>
          <mesh>
            <scale>1 1 1</scale>
            <uri>model://rovermk2_description/meshes/wheelFR.STL</uri>
          </mesh>
        </geometry>
      </visual>
    </link>
    <static>0</static>
    <plugin name='gz_ros2_control::GazeboSimROS2ControlPlugin' filename='libgz_ros2_control-system.so'>
      <parameters>/home/arpit/urdf_ws/install/rovermk2_description/share/rovermk2_description/config/controller.yaml</parameters>
    </plugin>
  </model>
</sdf>
