<?xml version="1.0" encoding="utf-8"?>
<robot name="rovermk2">

    <!-- Base Link  -->

    <link name="base_link">
        <inertial>
            <origin xyz="1.5107E-12 -0.010391 0.059342" rpy="0 0 0" />
            <!-- <mass value="3.9684" />
            <inertia ixx="0.068308" ixy="2.8787E-12" ixz="-8.8418E-14" iyy="0.03715"
                iyz="0.00010785" izz="0.091228" /> -->
            <mass value="20.0" />
            <inertia ixx="0.34424" ixy="1.4503E-11" ixz="-4.4546E-13"
                iyy="0.18723"
                iyz="0.00054354" izz="0.45979" />
        </inertial>
        <visual>
            <origin xyz="0 0 0" rpy="0 0 0" />
            <geometry>
                <mesh filename="package://rovermk2_description/meshes/base_link.STL" />
            </geometry>
            <material name="">
                <color rgba="0.96471 0.96471 0.95294 1" />
            </material>
        </visual>
        <collision>
            <origin xyz="0 0 0.05" rpy="0 0 0" />
            <geometry>
                <box size="0.28 0.35 0.15" />
            </geometry>
        </collision>
    </link>

    <!-- Suspension Links -->

    <link name="suspension_left">
        <inertial>
            <origin xyz="-0.085081 0.00042119 -0.0073347" rpy="0 0 0" />
            <!-- <mass value="0.69456" />
            <inertia ixx="0.00041573" ixy="-1.6646E-10" ixz="-3.1978E-09" iyy="0.0014467"
                iyz="2.2187E-10" izz="0.0017365" /> -->
            <mass value="5.0" />
            <inertia ixx="0.0029927" ixy="-1.1983E-09" ixz="-2.3018E-08"
                iyy="0.0104136"
                iyz="1.5973E-09" izz="0.0125038" />
        </inertial>
        <visual>
            <origin xyz="0.08875 0 0" rpy="0 0 0" />
            <geometry>
                <mesh filename="package://rovermk2_description/meshes/suspension_1.STL" />
            </geometry>
            <material name="">
                <color rgba="0.96471 0.96471 0.95294 1" />
            </material>
        </visual>
        <collision>
            <origin xyz="-0.01 0 -0.007" rpy="0 0 0" />
            <geometry>
                <box size="0.65 0.05 0.04" />
            </geometry>
        </collision>
    </link>

    <link name="suspension_right">
        <inertial>
            <origin xyz="0.0048172 -0.047933 -0.0073349" rpy="0 0 0" />
            <!-- <mass value="0.69456" />
                <inertia ixx="0.00041573" ixy="-2.7089E-10" ixz="3.1961E-09" iyy="0.0014467"
                    iyz="1.1348E-07" izz="0.0017365" /> -->
            <mass value="5.0" />
            <inertia ixx="0.0029927" ixy="-1.1983E-09" ixz="-2.3018E-08"
                iyy="0.0104136"
                iyz="1.5973E-09" izz="0.0125038" />
        </inertial>
        <visual>
            <origin xyz="0 0.0475 0" rpy="0 0 0" />
            <geometry>
                <mesh filename="package://rovermk2_description/meshes/suspension_2.STL" />
            </geometry>
            <material name="">
                <color rgba="0.96471 0.96471 0.95294 1" />
            </material>
        </visual>
        <collision>
            <origin xyz="0.005 0 -0.007" rpy="0 0 0" />
            <geometry>
                <box size="0.65 0.05 0.04" />
            </geometry>
        </collision>
    </link>

    <!-- Suspension Joints Closed Loop thus with gazebo tags -->

    <joint name="susleft_joint" type="fixed">
        <origin xyz="-0.175 -0.01 0.043" rpy="0 0 -1.5708" />
        <parent link="base_link" />
        <child link="suspension_left" />
        <axis xyz="0 1 0" />
        <limit lower="-0.174" upper="0.174" effort="100" velocity="1" />
    </joint>

    <joint name="susright_joint" type="fixed">
        <origin xyz="0.175 -0.01 0.043" rpy="0 1.7626E-05 -1.5708" />
        <parent link="base_link" />
        <child link="suspension_right" />
        <axis xyz="0 1 0" />
        <limit lower="-0.174" upper="0.174" effort="100" velocity="1" />
    </joint>


    <!-- Steer Joints and Links -->

    <!-- Steer Front Left Joint and Link -->

    <link name="steerFL">
        <inertial>
            <origin xyz="-2.2204E-15 -0.032335 -0.05247" rpy="0 0 0" />
            <!-- <mass value="0.1576" />
            <inertia ixx="0.00057382" ixy="-5.2157E-17" ixz="-1.2839E-16" iyy="0.00051647"
                iyz="-0.00013791" izz="0.00023455" /> -->
            <mass value="1.5" />
            <inertia ixx="0.0054624" ixy="-4.9661E-16" ixz="-1.2221E-15"
                iyy="0.0049171"
                iyz="-0.0013127" izz="0.0022330" />
        </inertial>
        <visual>
            <origin xyz="0 0 0" rpy="0 0 0" />
            <geometry>
                <mesh filename="package://rovermk2_description/meshes/Steer_FL_1.STL" />
            </geometry>
            <material name="">
                <color rgba="0.96078 0.96078 0.96471 1" />
            </material>
        </visual>
        <collision>
            <origin xyz="0 -0.032 -0.052" rpy="0 0 0" />
            <geometry>
                <box size="0.06 0.06 0.10" />
            </geometry>
        </collision>
    </link>
    <joint name="steerFL_joint" type="revolute">
        <origin xyz="-0.30875 0 -0.035" rpy="0 0 0" />
        <parent link="suspension_left" />
        <child link="steerFL" />
        <axis xyz="0 0 1" />
        <limit lower="-1.5708" upper="1.5708" effort="100" velocity="5.0"/>
        <dynamics damping="5.0" friction="2.0"/>
    </joint>

    <!-- Steer Front Right Joint and Link -->

    <link name="steer_FR">
        <inertial>
            <origin xyz="0.3075 0.025165 -0.08747" rpy="0 0 0" />
            <!-- <mass value="0.1576" />
            <inertia ixx="0.00057382" ixy="-5.2157E-17" ixz="-1.2839E-16" iyy="0.00051647"
                iyz="-0.00013791" izz="0.00023455" /> -->
            <mass value="1.5" />
            <inertia ixx="0.0054624" ixy="-4.9661E-16" ixz="-1.2221E-15"
                iyy="0.0049171"
                iyz="-0.0013127" izz="0.0022330" />
        </inertial>
        <visual>
            <origin xyz="-0.30751 -0.0475 0" rpy="0 0 0" />
            <geometry>
                <mesh filename="package://rovermk2_description/meshes/steer_FR.STL" />
            </geometry>
            <material name="">
                <color rgba="0.96078 0.96078 0.96471 1" />
            </material>
        </visual>
        <collision>
            <origin xyz="0 -0.022 -0.082" rpy="0 0 0" />
            <geometry>
                <box size="0.06 0.06 0.10" />
            </geometry>
        </collision>
    </link>
    <joint name="steerFR_joint" type="revolute">
        <origin xyz="-0.30751 0.0 0" rpy="0 0 3.1416" />
        <parent link="suspension_right" />
        <child link="steer_FR" />
        <axis xyz="5.9526E-05 0 1" />
        <limit lower="-1.5708" upper="1.5708" effort="100" velocity="5.0"/>
        <dynamics damping="5.0" friction="2.0"/>

    </joint>


    <!-- Steer Back Left Joint and Link -->

    <link name="steer_BL">
        <inertial>
            <origin xyz="-2.7756E-15 -0.032335 -0.05247" rpy="0 0 0" />
            <!-- <mass value="0.1576" />
            <inertia ixx="0.00057382" ixy="-5.2157E-17" ixz="-1.2839E-16" iyy="0.00051647"
                iyz="-0.00013791" izz="0.00023455" /> -->
            <mass value="1.5" />
            <inertia ixx="0.0054624" ixy="-4.9661E-16" ixz="-1.2221E-15"
                iyy="0.0049171"
                iyz="-0.0013127" izz="0.0022330" />
        </inertial>
        <visual>
            <origin xyz="0 0 0" rpy="0 0 0" />
            <geometry>
                <mesh filename="package://rovermk2_description/meshes/steer_BL.STL" />
            </geometry>
            <material name="">
                <color rgba="0.96078 0.96078 0.96471 1" />
            </material>
        </visual>
        <collision>
            <origin xyz="0 -0.032 -0.052" rpy="0 0 0" />
            <geometry>
                <box size="0.06 0.06 0.10" />
            </geometry>
        </collision>
    </link>
    <joint name="steerBL_joint" type="revolute">
        <origin xyz="0.30625 0 -0.035" rpy="0 0 0" />
        <parent link="suspension_left" />
        <child link="steer_BL" />
        <axis xyz="0 0 1" />
        <limit lower="-1.5708" upper="1.5708" effort="100" velocity="5.0"/>
        <dynamics damping="5.0" friction="2.0"/>

    </joint>

    <!-- Steer Back Right Joint and Link-->

    <link name="steer_BR">
        <inertial>
            <origin xyz="-0.30751 0.021928 -0.087669" rpy="0 0 0" />
            <!-- <mass value="0.1576" />
            <inertia ixx="0.00057382" ixy="-5.2157E-17" ixz="-1.2839E-16" iyy="0.00051647"
                iyz="-0.00013791" izz="0.00023455" /> -->
            <mass value="1.5" />
            <inertia ixx="0.0054624" ixy="-4.9661E-16" ixz="-1.2221E-15"
                iyy="0.0049171"
                iyz="-0.0013127" izz="0.0022330" />
        </inertial>

        <visual>
            <origin xyz="0.30625 -0.0475 0" rpy="0 0 0" />
            <geometry>
                <mesh filename="package://rovermk2_description/meshes/steer_BR.STL" />
            </geometry>
            <material name="">
                <color rgba="0.96078 0.96078 0.96471 1" />
            </material>
        </visual>
        <collision>
            <origin xyz="0 -0.022 -0.082" rpy="0 0 0" />
            <geometry>
                <box size="0.06 0.06 0.10" />
            </geometry>
        </collision>
    </link>
    <joint name="steerBR_joint" type="revolute">
        <origin xyz="0.30625 0.0 0.00019885" rpy="0 0 3.1416" />
        <parent link="suspension_right" />
        <child link="steer_BR" />
        <axis xyz="5.9526E-05 0 1" />
        <limit lower="-1.5708" upper="1.5708" effort="100" velocity="5.0"/>
        <dynamics damping="5.0" friction="2.0"/>

    </joint>


    <!-- All Wheels Joints and Links -->

    <link name="wheelFL">
        <inertial>
            <origin xyz="-1.2482E-05 1.1067E-05 -9.9464E-06" rpy="0 0 0" />
            <!-- <mass value="0.57698" />
            <inertia ixx="0.0021487" ixy="-1.7024E-08" ixz="-8.7398E-08" iyy="0.0038235"
                iyz="8.3831E-09" izz="0.0021487" /> -->
            <mass value="2.0" />
            <inertia ixx="0.0074488" ixy="-5.9009E-08" ixz="-3.0294E-07"
                iyy="0.0132488"
                iyz="2.9057E-08" izz="0.0074488" />
        </inertial>
        <visual>
            <origin xyz="0 0 0" rpy="0 0 0" />
            <geometry>
                <mesh filename="package://rovermk2_description/meshes/wheelFL.STL" />
            </geometry>
            <material name="">
                <color rgba="0.24706 0.24706 0.24706 1" />
            </material>
        </visual>
        <collision>
            <origin xyz="0 0 0" rpy="1.5708 0 0" />
            <geometry>
                <cylinder radius="0.09" length="0.07" />
            </geometry>
        </collision>
    </link>
    <joint name="wheelFL_joint" type="continuous">
        <origin xyz="0 0.008 -0.127" rpy="0 -0.031506 3.1416" />
        <parent link="steerFL" />
        <child link="wheelFL" />
        <axis xyz="0 1 0" />
        <!-- <limit lower="-1.5708" upper="1.5708" effort="100" velocity="0.25"/> -->
    </joint>

    <link name="wheelBL">
        <inertial>
            <origin xyz="-1.4946E-05 8.1816E-06 -7.8177E-06" rpy="0 0 0" />
            <!-- <mass value="0.57701" />
            <inertia ixx="0.0021482" ixy="-3.9981E-08" ixz="-7.3417E-08" iyy="0.0038226"
                iyz="-2.1036E-08" izz="0.0021482" /> -->
            <mass value="2.0" />
            <inertia ixx="0.0074488" ixy="-5.9009E-08" ixz="-3.0294E-07"
                iyy="0.0132488"
                iyz="2.9057E-08" izz="0.0074488" />
        </inertial>
        <visual>
            <origin xyz="0 0 0" rpy="0 0 0" />
            <geometry>
                <mesh filename="package://rovermk2_description/meshes/wheelBL.STL" />
            </geometry>
            <material name="">
                <color rgba="0.24706 0.24706 0.24706 1" />
            </material>
        </visual>
        <collision>
            <origin xyz="0 0 0" rpy="1.5708 0 0" />
            <geometry>
                <cylinder radius="0.09" length="0.07" />
            </geometry>
        </collision>
    </link>
    <joint name="wheelBL_joint" type="continuous">
        <origin xyz="0 0.008 -0.127" rpy="0 -0.19461 3.1416" />
        <parent link="steer_BL" />
        <child link="wheelBL" />
        <axis xyz="0 1 0" />
        <!-- <limit lower="0" upper="0" effort="0" velocity="0"/> -->
    </joint>

    <link name="wheelFR">
        <inertial>
            <origin xyz="-1.5082E-05 8.1816E-06 -6.5794E-06" rpy="0 0 0" />
            <!-- <mass value="0.57701" />
            <inertia ixx="0.0021482" ixy="-3.9981E-08" ixz="-7.3417E-08" iyy="0.0038226"
                iyz="-2.1036E-08" izz="0.0021482" /> -->
            <mass value="2.0" />
            <inertia ixx="0.0074488" ixy="-5.9009E-08" ixz="-3.0294E-07"
                iyy="0.0132488"
                iyz="2.9057E-08" izz="0.0074488" />
        </inertial>
        <visual>
            <origin xyz="0 0 0" rpy="0 0 0" />
            <geometry>
                <mesh filename="package://rovermk2_description/meshes/wheelFR.STL" />
            </geometry>
            <material name="">
                <color rgba="0.24706 0.24706 0.24706 1" />
            </material>
        </visual>
        <collision>
            <origin xyz="0 0 0" rpy="1.5708 0 0" />
            <geometry>
                <cylinder radius="0.09" length="0.07" />
            </geometry>
        </collision>
    </link>
    <joint name="wheelFR_joint" type="continuous">
        <origin xyz="0.0 0.0 -0.162" rpy="0 -0.48916 0" />
        <parent link="steer_FR" />
        <child link="wheelFR" />
        <axis xyz="0 1 0" />
        <!-- <limit lower="0" upper="0" effort="0" velocity="0"/> -->
    </joint>

    <link name="wheelBR">
        <inertial>
            <origin xyz="-1.3322E-05 9.8794E-06 -8.7944E-06" rpy="0 0 0" />
            <!-- <mass value="0.57701" />
            <inertia ixx="0.0021482" ixy="-3.9981E-08" ixz="-7.3417E-08" iyy="0.0038226"
                iyz="-2.1036E-08" izz="0.0021482" /> -->
            <mass value="2.0" />
            <inertia ixx="0.0074488" ixy="-5.9009E-08" ixz="-3.0294E-07"
                iyy="0.0132488"
                iyz="2.9057E-08" izz="0.0074488" />
        </inertial>
        <visual>
            <origin xyz="0 0 0" rpy="0 0 0" />
            <geometry>
                <mesh filename="package://rovermk2_description/meshes/wheelBR.STL" />
            </geometry>
            <material name="">
                <color rgba="0.24706 0.24706 0.24706 1" />
            </material>
        </visual>
        <collision>
            <origin xyz="0 0 0" rpy="1.5708 0 0" />
            <geometry>
                <cylinder radius="0.09" length="0.07" />
            </geometry>
        </collision>
    </link>
    <joint name="wheelBR_joint" type="continuous">
        <origin xyz="0 0.0 -0.1622" rpy="0 -0.069204 0" />
        <parent link="steer_BR" />
        <child link="wheelBR" />
        <axis xyz="0 1 0" />
        <!-- <limit lower="0" upper="0" effort="0" velocity="0"/> -->
    </joint>

</robot>
